Workbook

Sheet orders (2)
A1: OrderID | B1: CustomerID | C1: EmployeeID | D1: OrderDate | E1: RequiredDate | F1: ShippedDate | G1: ShipVia | H1: Freight | I1: ShipName | J1: ShipAddress | K1: ShipAddress_1 | L1: ShipCity | M1: ShipRegion | N1: ShipPostalCode | O1: ShipCountry
A2: 10248 | B2: VINET | C2: 5 | D2: 34550 | E2: 34578 | F2: 34562 | G2: 3 | H2: 32.38 | I2: Vins et alcools Chevalier | J2: 59 rue de l'Abbaye | K2: 59 rue de l'Abbaye | L2: Reims | N2: 51100 | O2: France
A3: 10249 | B3: TOMSP | C3: 6 | D3: 34551 | E3: 34593 | F3: 34556 | G3: 1 | H3: 11.61 | I3: Toms SpezialitÃ¤ten | J3: Luisenstr. 48 | K3: Luisenstr. 48 | L3: Münster | N3: 44087 | O3: Germany
A4: 10250 | B4: HANAR | C4: 4 | D4: 34554 | E4: 34582 | F4: 34558 | G4: 2 | H4: 65.83 | I4: Hanari Carnes | J4: Rua do PaÃ§o, 67 | K4: Rua do PaÃ§o, 67 | L4: Rio de Janeiro | M4: RJ | N4: 05454-876 | O4: Brazil
A5: 10251 | B5: VICTE | C5: 3 | D5: 34554 | E5: 34582 | F5: 34561 | G5: 1 | H5: 41.34 | I5: Victuailles en stock | J5: 2, rue du Commerce | K5: 2, rue du Commerce | L5: Lyon | N5: 69004 | O5: France
A6: 10252 | B6: SUPRD | C6: 4 | D6: 34555 | E6: 34583 | F6: 34557 | G6: 2 | H6: 51.3 | I6: SuprÃªmes dèlices | J6: Boulevard Tirou, 255 | K6: Boulevard Tirou, 255 | L6: Charleroi | N6: B-6000 | O6: Belgium
A7: 10253 | B7: HANAR | C7: 3 | D7: 34556 | E7: 34570 | F7: 34562 | G7: 2 | H7: 58.17 | I7: Hanari Carnes | J7: Rua do PaÃ§o, 67 | K7: Rua do PaÃ§o, 67 | L7: Rio de Janeiro | M7: RJ | N7: 05454-876 | O7: Brazil
A8: 10254 | B8: CHOPS | C8: 5 | D8: 34557 | E8: 34585 | F8: 34569 | G8: 2 | H8: 22.98 | I8: Chop-suey Chinese | J8: Hauptstr. 31 | K8: Hauptstr. 31 | L8: Bern | N8: 3012 | O8: Switzerland
A9: 10255 | B9: RICSU | C9: 9 | D9: 34558 | E9: 34586 | F9: 34561 | G9: 3 | H9: 148.33 | I9: Richter Supermarkt | J9: Starenweg 5 | K9: Starenweg 5 | L9: Genève | N9: 1204 | O9: Switzerland
A10: 10256 | B10: WELLI | C10: 3 | D10: 34561 | E10: 34589 | F10: 34563 | G10: 2 | H10: 13.97 | I10: Wellington Importadora | J10: Rua do Mercado, 12 | K10: Rua do Mercado, 12 | L10: Resende | M10: SP | N10: 08737-363 | O10: Brazil
A11: 10257 | B11: HILAA | C11: 4 | D11: 34562 | E11: 34590 | F11: 34568 | G11: 3 | H11: 81.91 | I11: HILARIÃ“N-Abastos | J11: Carrera 22 con Ave. Carlos Soublette 8-35 | K11: Carrera 22 con Ave. Carlos Soublette 8-35 | L11: San CristÃ³bal | M11: TÃ¡chira | N11: 5022 | O11: Venezuela
A12: 10258 | B12: ERNSH | C12: 1 | D12: 34563 | E12: 34591 | F12: 34569 | G12: 1 | H12: 140.51 | I12: Ernst Handel | J12: Kirchgasse 6 | K12: Kirchgasse 6 | L12: Graz | N12: 8010 | O12: Austria
A13: 10259 | B13: CENTC | C13: 4 | D13: 34564 | E13: 34592 | F13: 34571 | G13: 3 | H13: 3.25 | I13: Centro comercial Moctezuma | J13: Sierras de Granada 9993 | K13: Sierras de Granada 9993 | L13: Mèxico D.F. | N13: 5022 | O13: Mexico
A14: 10260 | B14: OTTIK | C14: 4 | D14: 34565 | E14: 34593 | F14: 34575 | G14: 1 | H14: 55.09 | I14: Ottilies KÃ¤seladen | J14: Mehrheimerstr. 369 | K14: Mehrheimerstr. 369 | L14: Köln | N14: 50739 | O14: Germany
A15: 10261 | B15: QUEDE | C15: 4 | D15: 34565 | E15: 34593 | F15: 34576 | G15: 2 | H15: 3.05 | I15: Que DelÃ­cia | J15: Rua da Panificadora, 12 | K15: Rua da Panificadora, 12 | L15: Rio de Janeiro | M15: RJ | N15: 02389-673 | O15: Brazil
A16: 10262 | B16: RATTC | C16: 8 | D16: 34568 | E16: 34596 | F16: 34571 | G16: 3 | H16: 48.29 | I16: Rattlesnake Canyon Grocery | J16: 2817 Milton Dr. | K16: 2817 Milton Dr. | L16: Albuquerque | M16: NM | N16: 87110 | O16: USA
A17: 10263 | B17: ERNSH | C17: 9 | D17: 34569 | E17: 34597 | F17: 34577 | G17: 3 | H17: 146.06 | I17: Ernst Handel | J17: Kirchgasse 6 | K17: Kirchgasse 6 | L17: Graz | N17: 8010 | O17: Austria
A18: 10264 | B18: FOLKO | C18: 6 | D18: 34570 | E18: 34598 | F18: 34600 | G18: 3 | H18: 3.67 | I18: Folk och fÃ¤ HB | J18: Ã…kergatan 24 | K18: Ã…kergatan 24 | L18: BrÃ¤cke | N18: S-844 67 | O18: Sweden
A19: 10265 | B19: BLONP | C19: 2 | D19: 34571 | E19: 34599 | F19: 34589 | G19: 1 | H19: 55.28 | I19: Blondel père et fils | J19: 24, place Klèber | K19: 24, place Klèber | L19: Strasbourg | N19: 67000 | O19: France
A20: 10266 | B20: WARTH | C20: 3 | D20: 34572 | E20: 34614 | F20: 34577 | G20: 3 | H20: 25.73 | I20: Wartian Herkku | J20: Torikatu 38 | K20: Torikatu 38 | L20: Oulu | N20: 90110 | O20: Finland
A21: 10267 | B21: FRANK | C21: 4 | D21: 34575 | E21: 34603 | F21: 34583 | G21: 1 | H21: 208.58 | I21: Frankenversand | J21: Berliner Platz 43 | K21: Berliner Platz 43 | L21: München | N21: 80805 | O21: Germany
A22: 10268 | B22: GROSR | C22: 8 | D22: 34576 | E22: 34604 | F22: 34579 | G22: 3 | H22: 66.29 | I22: GROSELLA-Restaurante | J22: 5Âª Ave. Los Palos Grandes | K22: 5Âª Ave. Los Palos Grandes | L22: Caracas | M22: DF | N22: 1081 | O22: Venezuela
A23: 10269 | B23: WHITC | C23: 5 | D23: 34577 | E23: 34591 | F23: 34586 | G23: 1 | H23: 4.56 | I23: White Clover Markets | J23: 1029 - 12th Ave. S. | K23: 1029 - 12th Ave. S. | L23: Seattle | M23: WA | N23: 98124 | O23: USA
A24: 10270 | B24: WARTH | C24: 1 | D24: 34578 | E24: 34606 | F24: 34579 | G24: 1 | H24: 136.54 | I24: Wartian Herkku | J24: Torikatu 38 | K24: Torikatu 38 | L24: Oulu | N24: 90110 | O24: Finland
A25: 10271 | B25: SPLIR | C25: 6 | D25: 34578 | E25: 34606 | F25: 34607 | G25: 2 | H25: 4.54 | I25: Split Rail Beer & Ale | J25: P.O. Box 555 | K25: P.O. Box 555 | L25: Lander | M25: WY | N25: 82520 | O25: USA
A26: 10272 | B26: RATTC | C26: 6 | D26: 34579 | E26: 34607 | F26: 34583 | G26: 2 | H26: 98.03 | I26: Rattlesnake Canyon Grocery | J26: 2817 Milton Dr. | K26: 2817 Milton Dr. | L26: Albuquerque | M26: NM | N26: 87110 | O26: USA
A27: 10273 | B27: QUICK | C27: 3 | D27: 34582 | E27: 34610 | F27: 34589 | G27: 3 | H27: 76.07 | I27: QUICK-Stop | J27: TaucherstraÃŸe 10 | K27: TaucherstraÃŸe 10 | L27: Cunewalde | N27: 1307 | O27: Germany
A28: 10274 | B28: VINET | C28: 6 | D28: 34583 | E28: 34611 | F28: 34593 | G28: 1 | H28: 6.01 | I28: Vins et alcools Chevalier | J28: 59 rue de l'Abbaye | K28: 59 rue de l'Abbaye | L28: Reims | N28: 51100 | O28: France
A29: 10275 | B29: MAGAA | C29: 1 | D29: 34584 | E29: 34612 | F29: 34586 | G29: 1 | H29: 26.93 | I29: Magazzini Alimentari Riuniti | J29: Via Ludovico il Moro 22 | K29: Via Ludovico il Moro 22 | L29: Bergamo | N29: 24100 | O29: Italy
A30: 10276 | B30: TORTU | C30: 8 | D30: 34585 | E30: 34599 | F30: 34591 | G30: 3 | H30: 13.84 | I30: Tortuga Restaurante | J30: Avda. Azteca 123 | K30: Avda. Azteca 123 | L30: Mèxico D.F. | N30: 5033 | O30: Mexico
A31: 10277 | B31: MORGK | C31: 2 | D31: 34586 | E31: 34614 | F31: 34590 | G31: 3 | H31: 125.77 | I31: Morgenstern Gesundkost | J31: Heerstr. 22 | K31: Heerstr. 22 | L31: Leipzig | N31: 4179 | O31: Germany
A32: 10278 | B32: BERGS | C32: 8 | D32: 34589 | E32: 34617 | F32: 34593 | G32: 2 | H32: 92.69 | I32: Berglunds snabbköp | J32: BerguvsvÃ¤gen 8 | K32: BerguvsvÃ¤gen 8 | L32: LuleÃ¥ | N32: S-958 22 | O32: Sweden
A33: 10279 | B33: LEHMS | C33: 8 | D33: 34590 | E33: 34618 | F33: 34593 | G33: 2 | H33: 25.83 | I33: Lehmanns Marktstand | J33: Magazinweg 7 | K33: Magazinweg 7 | L33: Frankfurt a.M. | N33: 60528 | O33: Germany
A34: 10280 | B34: BERGS | C34: 2 | D34: 34591 | E34: 34619 | F34: 34620 | G34: 1 | H34: 8.98 | I34: Berglunds snabbköp | J34: BerguvsvÃ¤gen 8 | K34: BerguvsvÃ¤gen 8 | L34: LuleÃ¥ | N34: S-958 22 | O34: Sweden
A35: 10281 | B35: ROMEY | C35: 4 | D35: 34591 | E35: 34605 | F35: 34598 | G35: 1 | H35: 2.94 | I35: Romero y tomillo | J35: Gran VÃ­a, 1 | K35: Gran VÃ­a, 1 | L35: Madrid | N35: 28001 | O35: Spain
A36: 10282 | B36: ROMEY | C36: 4 | D36: 34592 | E36: 34620 | F36: 34598 | G36: 1 | H36: 12.69 | I36: Romero y tomillo | J36: Gran VÃ­a, 1 | K36: Gran VÃ­a, 1 | L36: Madrid | N36: 28001 | O36: Spain
A37: 10283 | B37: LILAS | C37: 3 | D37: 34593 | E37: 34621 | F37: 34600 | G37: 3 | H37: 84.81 | I37: LILA-Supermercado | J37: Carrera 52 con Ave. BolÃ­var 65-98 Llano Largo | K37: Carrera 52 con Ave. BolÃ­var 65-98 Llano Largo | L37: Barquisimeto | M37: Lara | N37: 3508 | O37: Venezuela
A38: 10284 | B38: LEHMS | C38: 4 | D38: 34596 | E38: 34624 | F38: 34604 | G38: 1 | H38: 76.56 | I38: Lehmanns Marktstand | J38: Magazinweg 7 | K38: Magazinweg 7 | L38: Frankfurt a.M. | N38: 60528 | O38: Germany
A39: 10285 | B39: QUICK | C39: 1 | D39: 34597 | E39: 34625 | F39: 34603 | G39: 2 | H39: 76.83 | I39: QUICK-Stop | J39: TaucherstraÃŸe 10 | K39: TaucherstraÃŸe 10 | L39: Cunewalde | N39: 1307 | O39: Germany
A40: 10286 | B40: QUICK | C40: 8 | D40: 34598 | E40: 34626 | F40: 34607 | G40: 3 | H40: 229.24 | I40: QUICK-Stop | J40: TaucherstraÃŸe 10 | K40: TaucherstraÃŸe 10 | L40: Cunewalde | N40: 1307 | O40: Germany
...

Sheet Orders
A1: OrderID | B1: OrderDate | C1: CustomerID | D1: ProductID | E1: Quantity | F1: UnitPrice | G1: Discount | H1: ShippingCost | I1: Region | J1: PaymentMethod
A2: 10000 | B2: 2024-04-08 | C2: C1058 | D2: P1033 | E2: 4 | F2: 1800 | G2: 5 | H2: 110.69 | I2: R003 | J2: UPI
A3: 10001 | B3: 2024-06-14 | C3: C1489 | D3: P1036 | E3: 5 | F3: 1859 | G3: 15 | H3: 149.84 | I3: R002 | J3: Net Banking
A4: 10002 | B4: 2024-04-16 | C4: C1570 | D4: P1009 | E4: 5 | F4: 3193 | G4: 0 | H4: 28.75 | I4: R001 | J4: COD
A5: 10003 | B5: 2024-02-10 | C5: C1135 | D5: P1005 | E5: 1 | F5: 3828 | G5: 5 | H5: 46.64 | I5: R004 | J5: Net Banking
A6: 10004 | B6: 2024-03-25 | C6: C1691 | D6: P1021 | E6: 4 | F6: 3949 | G6: 20 | H6: 22.8 | I6: R004 | J6: Net Banking
A7: 10005 | B7: 2024-05-31 | C7: C1003 | D7: P1036 | E7: 1 | F7: 1859 | G7: 10 | H7: 121.23 | I7: R002 | J7: Debit Card
A8: 10006 | B8: 2024-05-07 | C8: C1675 | D8: P1022 | E8: 4 | F8: 3803 | G8: 5 | H8: 71.19 | I8: R004 | J8: Debit Card
A9: 10007 | B9: 2024-04-08 | C9: C1508 | D9: P1011 | E9: 2 | F9: 2225 | G9: 5 | H9: 177.95 | I9: R002 | J9: COD
A10: 10008 | B10: 2024-01-12 | C10: C1314 | D10: P1039 | E10: 2 | F10: 3016 | G10: 0 | H10: 115.72 | I10: R002 | J10: Credit Card
A11: 10009 | B11: 2024-03-16 | C11: C1950 | D11: P1007 | E11: 3 | F11: 4897 | G11: 0 | H11: 115.06 | I11: R002 | J11: UPI
A12: 10010 | B12: 2024-04-18 | C12: C1083 | D12: P1029 | E12: 1 | F12: 4723 | G12: 0 | H12: 169.47 | I12: R003 | J12: Credit Card
A13: 10011 | B13: 2024-04-12 | C13: C1762 | D13: P1013 | E13: 5 | F13: 2756 | G13: 10 | H13: 130.48 | I13: R003 | J13: COD
... A5001: 14999 | B5001: 2024-05-06 | C5001: C1109 | D5001: P1025 | E5001: 3 | F5001: 2588 | G5001: 10 | H5001: 164.88 | I5001: R002 | J5001: COD

Sheet pivote table1order details
A3: Row Labels | B3: Sum of Totalsales | C3: Count of OrderID
A4: ALFKI | B4: 4273 | C4: 12 | D4: =AVERAGE(B:B) -> 28128.734
A5: ANATR | B5: 1402.95 | C5: 10
A6: ANTON | B6: 7023.9775 | C6: 17
A7: AROUT | B7: 13390.65 | C7: 30
A8: BERGS | B8: 24927.577 | C8: 52
A9: BLAUS | B9: 3239.8 | C9: 14
A10: BLONP | B10: 18534.08 | C10: 26
A11: BOLID | B11: 4232.85 | C11: 6
A12: BONAP | B12: 21963.253 | C12: 44
A13: BOTTM | B13: 20801.6 | C13: 35
A14: BSBEV | B14: 6089.9 | C14: 22
A15: CACTU | B15: 1814.8 | C15: 11
A16: CENTC | B16: 100.8 | C16: 2
... A92: WOLZA | B92: 3531.95 | C92: 16
A93: (blank)
A94: Grand Total | B94: 1265793 | C94: 2155

Sheet Q2
A1: 1. How do customer order patterns vary by city or country?
A4: Argentina | B4: 14
A5: Spain | B5: 23
A6: Switzerland | B6: 17
A7: Italy | B7: 27
A8: Venezuela | B8: 43
A9: Belgium | B9: 19
A10: Norway | B10: 6
A11: Sweden | B11: 37
A12: USA | B12: 119
A13: France | B13: 75
A14: Mexico | B14: 27
A15: Brazil | B15: 81
... A24: Finland | B24: 22

Sheet Q3
A1: 3. Can we cluster customers based on total spend, order count, and preferred categories?
A3: WHITC | B3: Meat/Poultry | C3: 5
A4: CONSH | B4: Dairy Products | C4: 1
A5: BONAP | B5: Seafood | C5: 10
A6: GODOS | B6: Beverages | C6: 5
A7: ALFKI | B7: Produce | C7: 2
A8: OLDWO | B8: Confections | C8: 5
A9: WHITC | B9: Dairy Products | C9: 5
A10: FOLIG | B10: Condiments | C10: 1
A11: BONAP | B11: Confections | C11: 6
A12: TOMSP | B12: Confections | C12: 4
A13: FRANR | B13: Confections | C13: 2
A14: MEREP | B14: Confections | C14: 8
... A597: LILAS | B597: Condiments | C597: 3

Sheet Q1
A1: 1. What is the average number of orders per customer? Are there high-value repeat customers?
A2: TOMSP | B2: 6
A3: LONEP | B3: 8
A4: OLDWO | B4: 10
A5: WARTH | B5: 15
A6: MAGAA | B6: 10
A7: QUEEN | B7: 12
A8: VINET | B8: 5
A9: ANTON | B9: 7
A10: MORGK | B10: 5
A11: GOURL | B11: 9
A12: WOLZA | B12: 7
A13: GALED | B13: 5
... A90: BOTTM | B90: 13

Sheet Detail1
A1: Details for Sum of Totalsales - ProductID: 3
A3: OrderID | B3: ProductID | C3: UnitPrice | D3: Quantity | E3: Discount | F3: Totalsales | G3: Customerid
A4: 11077 | B4: 3 | C4: 10 | D4: 4 | E4: 0 | F4: 40 | G4: RATTC
A5: 11017 | B5: 3 | C5: 10 | D5: 25 | E5: 0 | F5: 250 | G5: ERNSH
A6: 10857 | B6: 3 | C6: 10 | D6: 30 | E6: 0 | F6: 300 | G6: BERGS
A7: 10849 | B7: 3 | C7: 10 | D7: 49 | E7: 0 | F7: 490 | G7: KOENE
A8: 10764 | B8: 3 | C8: 10 | D8: 20 | E8: 0.1 | F8: 180 | G8: ERNSH
A9: 10742 | B9: 3 | C9: 10 | D9: 20 | E9: 0 | F9: 200 | G9: BOTTM
A10: 10702 | B10: 3 | C10: 10 | D10: 6 | E10: 0 | F10: 60 | G10: ALFKI | I10: Row Labels | J10: Sum of Totalsales
A11: 10591 | B11: 3 | C11: 10 | D11: 14 | E11: 0 | F11: 140 | G11: VAFFE | I11: 3 | J11: 3044
A12: 10540 | B12: 3 | C12: 10 | D12: 60 | E12: 0 | F12: 600 | G12: QUICK | I12: Grand Total | J12: 3044
A13: 10485 | B13: 3 | C13: 8 | D13: 20 | E13: 0.1 | F13: 144 | G13: LINOD
A14: 10405 | B14: 3 | C14: 8 | D14: 50 | E14: 0 | F14: 400 | G14: LINOD
A15: 10289 | B15: 3 | C15: 8 | D15: 30 | E15: 0 | F15: 240 | G15: BSBEV

Sheet Q4
A1: Which product categories or products contribute most to order revenue? 5 .Are there any correlations between orders and customer location or product category?
A5: Beverages | B5: 286526.95
A6: Dairy Products | B6: 251330.5
A7: Meat/Poultry | B7: 178188.8
A8: Confections | B8: 177099.1
A9: Seafood | B9: 141623.09
A10: Condiments | B10: 113694.75
A11: Produce | B11: 105268.6
A12: Grains/Cereals | B12: 100726.8
A16: Beverages | B16: 286526.95
A17: Dairy Products | B17: 251330.5
A18: Meat/Poultry | B18: 178188.8
A19: Confections | B19: 177099.1
... A23: Grains/Cereals | B23: 100726.8

Sheet Q5
A1: 5. How frequently do different customer segments place orders?
A4: SAVEA | B4: 31 | C4: High Frequency
A5: ERNSH | B5: 28 | C5: High Frequency
A6: QUICK | B6: 28 | C6: High Frequency
A7: FOLKO | B7: 19 | C7: High Frequency
A8: HUNGO | B8: 19 | C8: High Frequency
A9: BERGS | B9: 18 | C9: High Frequency
A10: HILAA | B10: 18 | C10: High Frequency
A11: RATTC | B11: 17 | C11: High Frequency
A12: BONAP | B12: 16 | C12: High Frequency
A13: WARTH | B13: 15 | C13: High Frequency
A14: FRANK | B14: 15 | C14: High Frequency
A15: KOENE | B15: 14 | C15: High Frequency
... A92: CENTC | B92: 1 | C92: Low Frequency

Sheet Q6
A1: 1. What is the geographic and title-wise distribution of employees?
A2: ANS:-
A3: Employees by Country
A5: USA | B5: 4
A6: UK | B6: 4
A8: Employees by City
A10: London | B10: 4
A11: Seattle | B11: 2
A12: Kirkland | B12: 1
A13: Redmond | B13: 1
A16: 2. Title-Wise Distribution of Employees
A18: Sales Representative | B18: 6
A19: Inside Sales Coordinator | B19: 1
A20: Sales Manager | B20: 1
A22: Combined Geographic + Title Anal
A24: USA | B24: Sales Representative | C24: 3
A25: UK | B25: Sales Representative | C25: 3
A26: USA | B26: Inside Sales Coordinator | C26: 1
A27: UK | B27: Sales Manager | C27: 1

Sheet Q7
A1: 1. What trends can we observe in hire dates across employee titles?
A2: Sales Representative | B2: 1992 | C2: 2
A3: Sales Representative | B3: 1993 | C3: 2
A4: Sales Manager | B4: 1993 | C4: 1
A5: Sales Representative | B5: 1994 | C5: 2
A6: Inside Sales Coordinator | B6: 1994 | C6: 1

Sheet Q8
A1: 1. What patterns exist in employee title and courtesy title distributions?
A4: ANS:-
A5: Sales Representative | B5: Ms. | C5: 3
A6: Sales Representative | B6: Mr. | C6: 2
A7: Sales Manager | B7: Mr. | C7: 1
A8: Sales Representative | B8: Mrs. | C8: 1
A9: Inside Sales Coordinator | B9: Ms. | C9: 1

Sheet Q9
A1: 1. Are there correlations between product pricing, stock levels, and sales performance?
A2: ANS:-
A3: SQL QUERY
A5: SELECT
A6: p.productname,
A7: p.unitprice,
A8: p.unitsinstock,
A9: SUM(od.quantity) AS total_sales
A10: FROM products p
A11: JOIN order_details od
A12: ON p.productid = od.productid
A13: GROUP BY
... A20: ANSWER:-
A22: Camembert Pierrot | B22: 34 | C22: 19 | D22: 1577
A23: Raclette Courdavault | B23: 55 | C23: 79 | D23: 1496
A24: Gorgonzola Telino | B24: 12.5 | C24: 0 | D24: 1397
A25: Gnocchi di nonna Alice | B25: 38 | C25: 21 | D25: 1263
A26: Pavlova | B26: 17.45 | C26: 29 | D26: 1158
A27: Rhönbräu Klosterbier | B27: 7.75 | C27: 125 | D27: 1155
A28: Guaraná Fantástica | B28: 4.5 | C28: 20 | D28: 1125
A29: Boston Crab Meat | B29: 18.4 | C29: 123 | D29: 1103
A30: Tarte au sucre | B30: 49.3 | C30: 17 | D30: 1083
A31: Chang | B31: 19 | C31: 17 | D31: 1057
A32: Fløtemysost | B32: 21.5 | C32: 26 | D32: 1057
A33: Sir Rodney's Scones | B33: 10 | C33: 3 | D33: 1016
... A98: Mishi Kobe Niku | B98: 97 | C98: 29 | D98: 95

Sheet Q10
A2: 1. How does product demand change over months or seasons?
E20: 1 | F20: 4882
E21: 2 | F21: 5244
E22: 3 | F22: 5870
E23: 4 | F23: 5687
E24: 5 | F24: 6434
E25: 6 | F25: 2193
E26: 7 | F26: 1635
E27: 8 | F27: 3516
E28: 9 | F28: 3183
E29: 10 | F29: 3467
E30: 11 | F30: 4326
E31: 12 | F31: 3682

Sheet Q11
A1: 1. Can we identify anomalies in product sales or revenue performance?
A2: ANS:-
I3: 1 | J3: 4882
I4: 2 | J4: 5244
I5: 3 | J5: 5870
I6: 4 | J6: 5687
I7: 5 | J7: 6434
I8: 6 | J8: 2193
I9: 7 | J9: 1635
I10: 8 | J10: 3516
I11: 9 | J11: 3183
I12: 10 | J12: 3467
I13: 11 | J13: 4326
I14: 12 | J14: 3682

Sheet Q12
A1: Q12 Are there any regional trends in supplier distribution and pricing?
J4: France | K4: 76.75 | L4: 3
J5: Germany | K5: 37.601111 | L5: 3
A6: sql code | J6: Australia | K6: 33.83125 | L6: 2
J7: Japan | K7: 30.458333 | L7: 2
A8: SELECT | J8: Spain | K8: 29.5 | L8: 1
A9: s.country, | J9: Italy | K9: 27.36 | L9: 2
B10: AVG(p.unitprice) AS avg_price, | J10: Canada | K10: 27.3125 | L10: 2
B11: COUNT(DISTINCT s.supplierid) AS total_suppliers | J11: Singapore | K11: 26.483333 | L11: 1
A12: FROM supplyerss s | J12: UK | K12: 22.814286 | L12: 2
A13: JOIN products p | J13: USA | K13: 20.870833 | L13: 4
A14: ON s.supplierid = p.supplierid | J14: Norway | K14: 20 | L14: 1
A15: GROUP BY s.country | J15: Finland | K15: 18.083333 | L15: 1
A16: ORDER BY avg_price DESC; | J16: Sweden | K16: 18 | L16: 2
J17: Netherlands | K17: 11.125 | L17: 1
A18: ANS:- | J18: Denmark | K18: 10.75 | L18: 1
J19: Brazil | K19: 4.5 | L19: 1

Sheet Q13
A1: How are suppliers distributed across different product categories?
D2: SQL CODE :-
A3: ANS :-
A4: Beverages | B4: 8 | D4: SELECT
A5: Condiments | B5: 8 | D5: c.categoryname,
A6: Seafood | B6: 8 | E6: COUNT(DISTINCT p.supplierid) AS total_suppliers
A7: Confections | B7: 6 | D7: FROM products p
A8: Grains/Cereals | B8: 5 | D8: JOIN categories c
A9: Meat/Poultry | B9: 5 | D9: ON p.categoryid = c.categoryid
A10: Produce | B10: 5 | D10: GROUP BY c.categoryname
A11: Dairy Products | B11: 4 | D11: ORDER BY total_suppliers DESC;

Sheet Q14
A2: 1. How do supplier pricing and categories relate across different regions?
A3: SQL Query | B3: Ans:- | C3: France | D3: Beverages | E3: 140.75 | F3: 2
A4: SELECT | C4: Germany | D4: Meat/Poultry | E4: 123.79 | F4: 1
A5: s.country, | C5: Japan | D5: Meat/Poultry | E5: 97 | F5: 1
A6: c.categoryname, | C6: Australia | D6: Seafood | E6: 62.5 | F6: 1
A7: AVG(p.unitprice) AS average_price, | C7: Australia | D7: Produce | E7: 53 | F7: 1
A8: COUNT(p.productid) AS total_products | C8: Canada | D8: Confections | E8: 49.3 | F8: 1
A9: FROM supplyerss s | C9: Singapore | D9: Beverages | E9: 46 | F9: 1
A10: JOIN products p | C10: Germany | D10: Produce | E10: 45.6 | F10: 1
A11: ON s.supplierid = p.supplierid | C11: France | D11: Dairy Products | E11: 44.5 | F11: 2
A12: JOIN categories c | C12: Australia | D12: Condiments | E12: 43.9 | F12: 1
A13: ON p.categoryid = c.categoryid | C13: Australia | D13: Meat/Poultry | E13: 35.9 | F13: 2
A14: GROUP BY | C14: Germany | D14: Grains/Cereals | E14: 33.25 | F14: 1
A15: s.country, | C15: USA | D15: Produce | E15: 30 | F15: 1
... A17: ORDER BY average_price DESC; | C17: Spain | D17: Dairy Products | E17: 29.5 | F17: 2
C18: Italy | D18: Grains/Cereals | E18: 28.75 | F18: 2
C19: Canada | D19: Condiments | E19: 28.5 | F19: 1
C20: UK | D20: Confections | E20: 28.175 | F20: 4
C21: Italy | D21: Dairy Products | E21: 26.433333 | F21: 3
C22: Germany | D22: Seafood | E22: 25.89 | F22: 1
C23: USA | D23: Condiments | E23: 24.4 | F23: 6
C24: Sweden | D24: Seafood | E24: 20 | F24: 3
C25: Norway | D25: Dairy Products | E25: 20 | F25: 3
C26: Singapore | D26: Condiments | E26: 19.45 | F26: 1
C27: UK | D27: Beverages | E27: 18.5 | F27: 2
C28: Japan | D28: Seafood | E28: 18.5 | F28: 2
C29: Finland | D29: Confections | E29: 18.125 | F29: 2
... C47: Brazil | D47: Beverages | E47: 4.5 | F47: 1

Sheet orderDetails
A1: OrderID | B1: ProductID | C1: UnitPrice | D1: Quantity | E1: Discount | F1: Totalsales | G1: Customerid
A2: 10248 | B2: 11 | C2: 14 | D2: 12 | E2: 0 | F2: 168 | G2: =VLOOKUP(orderDetails[[#This Row],[OrderID]],'orders (2)'!A:B,2,0) -> VINET
A3: 10248 | B3: 42 | C3: 9.8 | D3: 10 | E3: 0 | F3: 98 | G3: =VLOOKUP(orderDetails[[#This Row],[OrderID]],'orders (2)'!A:B,2,0) -> VINET
A4: 10248 | B4: 72 | C4: 34.8 | D4: 5 | E4: 0 | F4: 174 | G4: =VLOOKUP(orderDetails[[#This Row],[OrderID]],'orders (2)'!A:B,2,0) -> VINET
A5: 10249 | B5: 14 | C5: 18.6 | D5: 9 | E5: 0 | F5: 167.4 | G5: =VLOOKUP(orderDetails[[#This Row],[OrderID]],'orders (2)'!A:B,2,0) -> TOMSP
A6: 10249 | B6: 51 | C6: 42.4 | D6: 40 | E6: 0 | F6: 1696 | G6: =VLOOKUP(orderDetails[[#This Row],[OrderID]],'orders (2)'!A:B,2,0) -> TOMSP
A7: 10250 | B7: 41 | C7: 7.7 | D7: 10 | E7: 0 | F7: 77 | G7: =VLOOKUP(orderDetails[[#This Row],[OrderID]],'orders (2)'!A:B,2,0) -> HANAR
A8: 10250 | B8: 51 | C8: 42.4 | D8: 35 | E8: 0.15 | F8: 1261.4 | G8: =VLOOKUP(orderDetails[[#This Row],[OrderID]],'orders (2)'!A:B,2,0) -> HANAR
A9: 10250 | B9: 65 | C9: 16.8 | D9: 15 | E9: 0.15 | F9: 214.2 | G9: =VLOOKUP(orderDetails[[#This Row],[OrderID]],'orders (2)'!A:B,2,0) -> HANAR
A10: 10251 | B10: 22 | C10: 16.8 | D10: 6 | E10: 0.05 | F10: 95.76 | G10: =VLOOKUP(orderDetails[[#This Row],[OrderID]],'orders (2)'!A:B,2,0) -> VICTE
A11: 10251 | B11: 57 | C11: 15.6 | D11: 15 | E11: 0.05 | F11: 222.3 | G11: =VLOOKUP(orderDetails[[#This Row],[OrderID]],'orders (2)'!A:B,2,0) -> VICTE
A12: 10251 | B12: 65 | C12: 16.8 | D12: 20 | E12: 0 | F12: 336 | G12: =VLOOKUP(orderDetails[[#This Row],[OrderID]],'orders (2)'!A:B,2,0) -> VICTE
A13: 10252 | B13: 20 | C13: 64.8 | D13: 40 | E13: 0.05 | F13: 2462.4 | G13: =VLOOKUP(orderDetails[[#This Row],[OrderID]],'orders (2)'!A:B,2,0) -> SUPRD
... A2156: 11077 | B2156: 77 | C2156: 13 | D2156: 2 | E2156: 0 | F2156: 26 | G2156: =VLOOKUP(orderDetails[[#This Row],[OrderID]],'orders (2)'!A:B,2,0) -> RATTC

Sheet Returns
A1: Return_ID | B1: Order_ID | C1: Return_Date | D1: Return_Reason
A2: R00001 | B2: 11312 | C2: 45207 | D2: Late Delivery
A3: R00002 | B3: 11017 | C3: 45283 | D3: Wrong Item Delivered
A4: R00003 | B4: 11527 | C4: 45481 | D4: Late Delivery
A5: R00004 | B5: 12829 | C5: 45302 | D5: Damaged Item
A6: R00005 | B6: 10348 | C6: 45847 | D6: Damaged Item
A7: R00006 | B7: 12903 | C7: 45777 | D7: Wrong Item Delivered
A8: R00007 | B8: 11577 | C8: 45454 | D8: Changed Mind
A9: R00008 | B9: 11507 | C9: 45713 | D9: Wrong Item Delivered
A10: R00009 | B10: 12789 | C10: 45514 | D10: Damaged Item
A11: R00010 | B11: 11720 | C11: 45727 | D11: Changed Mind
A12: R00011 | B12: 11172 | C12: 45539 | D12: Late Delivery
A13: R00012 | B13: 12064 | C13: 45811 | D13: Damaged Item
... A1001: R01000 | B1001: 12378 | C1001: 45257 | D1001: Damaged Item

Sheet Customers
A1: Customer_ID | B1: First_Name | C1: Last_Name | D1: Email | E1: City | F1: Country
A2: C1000 | B2: Linda | C2: Ayala | D2: hamiltonandrew@yahoo.com | E2: Barnestown | F2: China
A3: C1001 | B3: Sarah | C3: Turner | D3: jacksonthomas@sullivan.info | E3: Port Levi | F3: Kazakhstan
A4: C1002 | B4: Krista | C4: Jones | D4: hannah64@gmail.com | E4: South Michael | F4: Bangladesh
A5: C1003 | B5: Kelly | C5: Krueger | D5: alexanderrodriguez@horton.com | E5: Moodyburgh | F5: Central African Republic
A6: C1004 | B6: Rachel | C6: Moore | D6: pwong@graham.net | E6: New Sophia | F6: Azerbaijan
A7: C1005 | B7: Jennifer | C7: Bailey | D7: turnersteven@henderson-wilson.com | E7: North Allen | F7: Greenland
A8: C1006 | B8: Mary | C8: Rivera | D8: cruiz@hotmail.com | E8: Hernandezmouth | F8: Egypt
A9: C1007 | B9: Travis | C9: Montgomery | D9: kennethgallegos@williams-smith.biz | E9: North Tyler | F9: Papua New Guinea
A10: C1008 | B10: Justin | C10: Goodwin | D10: mmclaughlin@hotmail.com | E10: West Maria | F10: United Arab Emirates
A11: C1009 | B11: Ashley | C11: Reed | D11: freemantodd@hotmail.com | E11: Jeremyfort | F11: Nauru
A12: C1010 | B12: Martin | C12: Sellers | D12: jenniferrice@yahoo.com | E12: Reynoldsburgh | F12: Lao People's Democratic Republic
... A51: C1048 | B51: Heather | C51: Lambert | D51: tammypalmer@hotmail.com | E51: New Sean | F51: Comoros
A52: C1049 | B52: Dustin | C52: Jones | E52: Danielview | F52: China
A53: C1050 | B53: John | C53: Murphy | E53: Hillmouth | F53: Argentina
A54: C1051 | B54: Melissa | C54: Hernandez | E54: Frankberg | F54: Turks and Caicos Islands
A55: C1052 | B55: Rhonda | C55: Benjamin | E55: Stephanieville | F55: Aruba
A56: C1053 | B56: Erik | C56: Floyd | D56: kelleycarlos@butler.com | E56: Port Markfort | F56: Estonia
A57: C1054 | B57: Margaret | C57: Hill | D57: kimberly79@gmail.com | E57: Donaldfurt | F57: Senegal
A58: C1055 | B58: Michael | C58: Rivera | D58: qgill@hernandez-luna.com | E58: Lake Ryanmouth | F58: Mexico
A59: C1056 | B59: Jeremy | C59: Hampton | D59: zhall@yahoo.com | E59: Thompsonton | F59: Liechtenstein
A60: C1057 | B60: Mr. | C60: Matthew | D60: pfitzgerald@cline.com | E60: Marioshire | F60: Netherlands
A61: C1058 | B61: Ronald | C61: Vance | D61: schneiderchristopher@hotmail.com | E61: New Brianberg | F61: Sudan
A62: C1059 | B62: Nicholas | C62: Sims | D62: karenshaw@martinez.com | E62: Brownland | F62: Wallis and Futuna
A63: C1060 | B63: Stephanie | C63: Atkinson | D63: kristin39@miller-ferguson.com | E63: East Curtis | F63: Poland
A64: C1061 | B64: Robin | C64: Riley | D64: henrysarah@yahoo.com | E64: Lake Jimmy | F64: Turks and Caicos Islands
A65: C1062 | B65: Christy | C65: Johnson | D65: robertheath@yahoo.com | E65: Teresamouth | F65: Lao People's Democratic Republic
A66: C1063 | B66: Steven | C66: Fernandez | D66: christopher18@gmail.com | E66: South Matthewland | F66: Malaysia
A67: C1064 | B67: Brittany | C67: Long | D67: iantate@gmail.com | E67: Moraleston | F67: Macao
... A97: C1093 | B97: Marcia | C97: Johns | D97: ryan64@frazier.info | E97: Jaytown | F97: Suriname
A98: C1094 | B98: Samantha | C98: Valentine | E98: Alexanderburgh | F98: Seychelles
A99: C1095 | B99: Lawrence | C99: Ruiz | D99: zstewart@gmail.com | E99: Jamiefurt | F99: Armenia
A100: C1096 | B100: Mr. | C100: Jason | D100: beardlindsey@hotmail.com | E100: Stephenfurt | F100: Cook Islands
A101: C1097 | B101: Patricia | C101: Hanson | D101: prosario@martin.com | E101: South Timothy | F101: Andorra
A102: C1098 | B102: Carol | C102: Jennings | D102: castillolindsey@robles.com | E102: Laurabury | F102: Fiji
A103: C1099 | B103: Linda | C103: Jones | D103: vallen@underwood.com | E103: New Danieltown | F103: Gabon
A104: C1100 | B104: Carlos | C104: Smith | D104: oduran@riley-miller.com | E104: New Brendantown | F104: Dominica
A105: C1101 | B105: Susan | C105: Cohen | D105: sedwards@patton.info | E105: Sarahport | F105: Uzbekistan
A106: C1102 | B106: Lisa | C106: Thompson | D106: cheryl61@byrd.com | E106: Jamesshire | F106: Iceland
A107: C1103 | B107: Linda | C107: Rich | D107: nmorales@yahoo.com | E107: North Brian | F107: Oman
...

Sheet Products
A1: Product_ID | B1: Product_Name | C1: Category | D1: Sub_Category | E1: Unit_Cost | F1: Unit_Price
A2: P1000 | B2: Mobile 242 | C2: Electronics | D2: Mobile | E2: 150.89 | F2: 203.24
A3: P1001 | B3: Headphones 704 | C3: Electronics | D3: Headphones | E3: 150.73 | F3: 230.2
A4: P1002 | B4: Fiction 617 | C4: Books | D4: Fiction | E4: 15.66 | F4: 20.85
A5: P1003 | B5: Fitness 818 | C5: Sports | D5: Fitness | E5: 116.64 | F5: 190.08
A6: P1004 | B6: Outdoor 928 | C6: Sports | D6: Outdoor | E6: 51.88 | F6: 80.6
A7: P1005 | B7: Mobile 259 | C7: Electronics | D7: Mobile | E7: 142.65 | F7: 200.3
A8: P1006 | B8: Shoes 467 | C8: Apparel | D8: Shoes | E8: 29.42 | F8: 42.01
A9: P1007 | B9: Decor 570 | C9: Home & Kitchen | D9: Decor | E9: 60.26 | F9: 73.88
A10: P1008 | B10: Fitness 665 | C10: Sports | D10: Fitness | E10: 194.89 | F10: 278.13
A11: P1009 | B11: Decor 691 | C11: Home & Kitchen | D11: Decor | E11: 127.52 | F11: 218.95
A12: P1010 | B12: Jackets 891 | C12: Apparel | D12: Jackets | E12: 23.22 | F12: 37.08
A13: P1011 | B13: Cookware 489 | C13: Home & Kitchen | D13: Cookware | E13: 172.51 | F13: 296.7
... A501: P1499 | B501: Outdoor 938 | C501: Sports | D501: Outdoor | E501: 119.72 | F501: 199.16

Sheet Region Info
A1: Region_Code | B1: Region_Name
A2: R001 | B2: East
A3: R002 | B3: West
A4: R003 | B4: North
A5: R004 | B5: South
